Workbook
Name Globals: INPUT!$A$4:$B$15
Name Lessons: INPUT!$A$18:$D$24
Name Steps: INPUT!$A$27:$A$45
Name Takes: INPUT!$A$48:$I$156

Sheet MAIN
A1: title_text | B1: order | C1: app-repeat | D1: app-ai | E1: mirror | F1: background | G1: character | H1: phrase | I1: directions | J1: props | K1: effect | L1: bgsound | M1: endsoundeffect | N1: h3 | O1: previousline | P1: filename | Q1: join | R1: video_file | S1: footer_text | T1: bgmusic | U1: subtitle_text | V1: foreground | W1: overlay | X1: image | Y1: course_id | Z1: course_name | AA1: lesson_id | AB1: lesson_title | AC1: response_type | AD1: unit | AE1: mission | AF1: recap_sources | AG1: recap_overlay | AH1: intro_video | AI1: success_video | AJ1: success_srt | AK1: success_srt_es | AL1: success_srt_pt | AM1: success_srt_bn | AN1: srt | AO1: lesson_title_es | AP1: lesson_title_pt | AQ1: lesson_title_bn | AR1: mission_es | AS1: mission_pt | AT1: mission_bn | AU1: cue_es | AV1: cue_pt | AW1: cue_bn | AX1: cue_alt_es | AY1: cue_alt_pt | AZ1: cue_alt_bn | BA1: subtitle_text_es | BB1: subtitle_text_pt | BC1: subtitle_text_bn | BD1: phrase_es | BE1: phrase_pt | BF1: phrase_bn | BG1: _step
A2: =INPUT!$B$5 | B2: 01 | G2: =INPUT!$B$6 | H2: =IFERROR(VLOOKUP($P$2,INPUT!$A$48:$I$156,6,FALSE),"") | P2: wouldyourather_a0101 | Q2: =IFERROR(VLOOKUP($P$2,INPUT!$A$48:$I$156,4,FALSE),"") | R2: =IFERROR(VLOOKUP($P$2,INPUT!$A$48:$I$156,3,FALSE),"") | U2: ="<aside><strong>🅰1️⃣"&$H$2&"</strong><br><br>🅰2️⃣___________<br><br>🅱1️⃣___________<br><br>🅱2️⃣___________></mark>" | Y2: =INPUT!$B$7 | Z2: =INPUT!$B$8 | AA2: =IFERROR(VLOOKUP($P$2,INPUT!$A$48:$I$156,5,FALSE),"") | AB2: =IFERROR(VLOOKUP($AA$2,INPUT!$A$18:$D$24,2,FALSE),"") | AC2: =INPUT!$B$9 | AF2: =IFERROR(VLOOKUP($AA$2,INPUT!$A$18:$D$24,3,FALSE),"") | AG2: =INPUT!$B$10 | AH2: =IFERROR(VLOOKUP($AA$2,INPUT!$A$18:$D$24,4,FALSE),"") | AI2: =INPUT!$B$11 | AJ2: =INPUT!$B$12 | AK2: =INPUT!$B$13 | AL2: =INPUT!$B$14 | AM2: =INPUT!$B$15 | BD2: =IFERROR(VLOOKUP($P$2,INPUT!$A$48:$I$156,7,FALSE),"") | BE2: =IFERROR(VLOOKUP($P$2,INPUT!$A$48:$I$156,8,FALSE),"") | BF2: =IFERROR(VLOOKUP($P$2,INPUT!$A$48:$I$156,9,FALSE),"") | BG2: =IF(TRIM($Q$2)<>"",TRIM($Q$2),TRIM($R$2))
A3: =INPUT!$B$5 | B3: 02 | G3: =INPUT!$B$6 | H3: =IFERROR(VLOOKUP($P$3,INPUT!$A$48:$I$156,6,FALSE),"") | P3: wouldyourather_a0102 | Q3: =IFERROR(VLOOKUP($P$3,INPUT!$A$48:$I$156,4,FALSE),"") | R3: =IFERROR(VLOOKUP($P$3,INPUT!$A$48:$I$156,3,FALSE),"") | U3: ="<aside>🅰1️⃣"&$H$2&"<br><br><strong>🅰2️⃣"&$H$3&"</strong><br><br>🅱1️⃣___________<br><br>🅱2️⃣___________</mark>" | Y3: =INPUT!$B$7 | Z3: =INPUT!$B$8 | AA3: =IFERROR(VLOOKUP($P$3,INPUT!$A$48:$I$156,5,FALSE),"") | AB3: =IFERROR(VLOOKUP($AA$3,INPUT!$A$18:$D$24,2,FALSE),"") | AC3: =INPUT!$B$9 | AF3: =IFERROR(VLOOKUP($AA$3,INPUT!$A$18:$D$24,3,FALSE),"") | AG3: =INPUT!$B$10 | AH3: =IFERROR(VLOOKUP($AA$3,INPUT!$A$18:$D$24,4,FALSE),"") | AI3: =INPUT!$B$11 | AJ3: =INPUT!$B$12 | AK3: =INPUT!$B$13 | AL3: =INPUT!$B$14 | AM3: =INPUT!$B$15 | BD3: =IFERROR(VLOOKUP($P$3,INPUT!$A$48:$I$156,7,FALSE),"") | BE3: =IFERROR(VLOOKUP($P$3,INPUT!$A$48:$I$156,8,FALSE),"") | BF3: =IFERROR(VLOOKUP($P$3,INPUT!$A$48:$I$156,9,FALSE),"") | BG3: =IF(TRIM($Q$3)<>"",TRIM($Q$3),TRIM($R$3))
A4: =INPUT!$B$5 | B4: 03 | G4: =INPUT!$B$6 | H4: =IFERROR(VLOOKUP($P$4,INPUT!$A$48:$I$156,6,FALSE),"") | P4: wouldyourather_a0103 | Q4: =IFERROR(VLOOKUP($P$4,INPUT!$A$48:$I$156,4,FALSE),"") | R4: =IFERROR(VLOOKUP($P$4,INPUT!$A$48:$I$156,3,FALSE),"") | U4: ="<aside>🅰1️⃣"&$H$2&"<br><br>🅰2️⃣"&$H$3&"<br><br><strong>🅱1️⃣"&$H$4&"</strong><br><br>🅱2️⃣___________</mark>" | Y4: =INPUT!$B$7 | Z4: =INPUT!$B$8 | AA4: =IFERROR(VLOOKUP($P$4,INPUT!$A$48:$I$156,5,FALSE),"") | AB4: =IFERROR(VLOOKUP($AA$4,INPUT!$A$18:$D$24,2,FALSE),"") | AC4: =INPUT!$B$9 | AF4: =IFERROR(VLOOKUP($AA$4,INPUT!$A$18:$D$24,3,FALSE),"") | AG4: =INPUT!$B$10 | AH4: =IFERROR(VLOOKUP($AA$4,INPUT!$A$18:$D$24,4,FALSE),"") | AI4: =INPUT!$B$11 | AJ4: =INPUT!$B$12 | AK4: =INPUT!$B$13 | AL4: =INPUT!$B$14 | AM4: =INPUT!$B$15 | BD4: =IFERROR(VLOOKUP($P$4,INPUT!$A$48:$I$156,7,FALSE),"") | BE4: =IFERROR(VLOOKUP($P$4,INPUT!$A$48:$I$156,8,FALSE),"") | BF4: =IFERROR(VLOOKUP($P$4,INPUT!$A$48:$I$156,9,FALSE),"") | BG4: =IF(TRIM($Q$4)<>"",TRIM($Q$4),TRIM($R$4))
A5: =INPUT!$B$5 | B5: 04 | G5: =INPUT!$B$6 | H5: =IFERROR(VLOOKUP($P$5,INPUT!$A$48:$I$156,6,FALSE),"") | P5: wouldyourather_a0104 | Q5: =IFERROR(VLOOKUP($P$5,INPUT!$A$48:$I$156,4,FALSE),"") | R5: =IFERROR(VLOOKUP($P$5,INPUT!$A$48:$I$156,3,FALSE),"") | U5: ="<aside>🅰1️⃣"&$H$2&"<br><br>🅰2️⃣"&$H$3&"<br><br>🅱1️⃣"&$H$4&"<br><br><strong>🅱2️⃣"&$H$5&"</mark>" | Y5: =INPUT!$B$7 | Z5: =INPUT!$B$8 | AA5: =IFERROR(VLOOKUP($P$5,INPUT!$A$48:$I$156,5,FALSE),"") | AB5: =IFERROR(VLOOKUP($AA$5,INPUT!$A$18:$D$24,2,FALSE),"") | AC5: =INPUT!$B$9 | AF5: =IFERROR(VLOOKUP($AA$5,INPUT!$A$18:$D$24,3,FALSE),"") | AG5: =INPUT!$B$10 | AH5: =IFERROR(VLOOKUP($AA$5,INPUT!$A$18:$D$24,4,FALSE),"") | AI5: =INPUT!$B$11 | AJ5: =INPUT!$B$12 | AK5: =INPUT!$B$13 | AL5: =INPUT!$B$14 | AM5: =INPUT!$B$15 | BD5: =IFERROR(VLOOKUP($P$5,INPUT!$A$48:$I$156,7,FALSE),"") | BE5: =IFERROR(VLOOKUP($P$5,INPUT!$A$48:$I$156,8,FALSE),"") | BF5: =IFERROR(VLOOKUP($P$5,INPUT!$A$48:$I$156,9,FALSE),"") | BG5: =IF(TRIM($Q$5)<>"",TRIM($Q$5),TRIM($R$5))
A6: =INPUT!$B$5 | B6: 01 | G6: =INPUT!$B$6 | H6: =IFERROR(VLOOKUP($P$6,INPUT!$A$48:$I$156,6,FALSE),"") | P6: wouldyourather_a0201 | Q6: =IFERROR(VLOOKUP($P$6,INPUT!$A$48:$I$156,4,FALSE),"") | R6: =IFERROR(VLOOKUP($P$6,INPUT!$A$48:$I$156,3,FALSE),"") | U6: ="<aside><strong>🅰1️⃣"&$H$6&"</strong><br><br>🅰2️⃣___________<br><br>🅱1️⃣___________<br><br>🅱2️⃣___________></mark>" | Y6: =INPUT!$B$7 | Z6: =INPUT!$B$8 | AA6: =IFERROR(VLOOKUP($P$6,INPUT!$A$48:$I$156,5,FALSE),"") | AB6: =IFERROR(VLOOKUP($AA$6,INPUT!$A$18:$D$24,2,FALSE),"") | AC6: =INPUT!$B$9 | AF6: =IFERROR(VLOOKUP($AA$6,INPUT!$A$18:$D$24,3,FALSE),"") | AG6: =INPUT!$B$10 | AH6: =IFERROR(VLOOKUP($AA$6,INPUT!$A$18:$D$24,4,FALSE),"") | AI6: =INPUT!$B$11 | AJ6: =INPUT!$B$12 | AK6: =INPUT!$B$13 | AL6: =INPUT!$B$14 | AM6: =INPUT!$B$15 | BD6: =IFERROR(VLOOKUP($P$6,INPUT!$A$48:$I$156,7,FALSE),"") | BE6: =IFERROR(VLOOKUP($P$6,INPUT!$A$48:$I$156,8,FALSE),"") | BF6: =IFERROR(VLOOKUP($P$6,INPUT!$A$48:$I$156,9,FALSE),"") | BG6: =IF(TRIM($Q$6)<>"",TRIM($Q$6),TRIM($R$6))
A7: =INPUT!$B$5 | B7: 02 | G7: =INPUT!$B$6 | H7: =IFERROR(VLOOKUP($P$7,INPUT!$A$48:$I$156,6,FALSE),"") | P7: wouldyourather_a0202 | Q7: =IFERROR(VLOOKUP($P$7,INPUT!$A$48:$I$156,4,FALSE),"") | R7: =IFERROR(VLOOKUP($P$7,INPUT!$A$48:$I$156,3,FALSE),"") | U7: ="<aside>🅰1️⃣"&$H$6&"<br><br><strong>🅰2️⃣"&$H$7&"</strong><br><br>🅱1️⃣___________<br><br>🅱2️⃣___________</mark>" | Y7: =INPUT!$B$7 | Z7: =INPUT!$B$8 | AA7: =IFERROR(VLOOKUP($P$7,INPUT!$A$48:$I$156,5,FALSE),"") | AB7: =IFERROR(VLOOKUP($AA$7,INPUT!$A$18:$D$24,2,FALSE),"") | AC7: =INPUT!$B$9 | AF7: =IFERROR(VLOOKUP($AA$7,INPUT!$A$18:$D$24,3,FALSE),"") | AG7: =INPUT!$B$10 | AH7: =IFERROR(VLOOKUP($AA$7,INPUT!$A$18:$D$24,4,FALSE),"") | AI7: =INPUT!$B$11 | AJ7: =INPUT!$B$12 | AK7: =INPUT!$B$13 | AL7: =INPUT!$B$14 | AM7: =INPUT!$B$15 | BD7: =IFERROR(VLOOKUP($P$7,INPUT!$A$48:$I$156,7,FALSE),"") | BE7: =IFERROR(VLOOKUP($P$7,INPUT!$A$48:$I$156,8,FALSE),"") | BF7: =IFERROR(VLOOKUP($P$7,INPUT!$A$48:$I$156,9,FALSE),"") | BG7: =IF(TRIM($Q$7)<>"",TRIM($Q$7),TRIM($R$7))
A8: =INPUT!$B$5 | B8: 03 | G8: =INPUT!$B$6 | H8: =IFERROR(VLOOKUP($P$8,INPUT!$A$48:$I$156,6,FALSE),"") | P8: wouldyourather_a0203 | Q8: =IFERROR(VLOOKUP($P$8,INPUT!$A$48:$I$156,4,FALSE),"") | R8: =IFERROR(VLOOKUP($P$8,INPUT!$A$48:$I$156,3,FALSE),"") | U8: ="<aside>🅰1️⃣"&$H$6&"<br><br>🅰2️⃣"&$H$7&"<br><br><strong>🅱1️⃣"&$H$8&"</strong><br><br>🅱2️⃣___________</mark>" | Y8: =INPUT!$B$7 | Z8: =INPUT!$B$8 | AA8: =IFERROR(VLOOKUP($P$8,INPUT!$A$48:$I$156,5,FALSE),"") | AB8: =IFERROR(VLOOKUP($AA$8,INPUT!$A$18:$D$24,2,FALSE),"") | AC8: =INPUT!$B$9 | AF8: =IFERROR(VLOOKUP($AA$8,INPUT!$A$18:$D$24,3,FALSE),"") | AG8: =INPUT!$B$10 | AH8: =IFERROR(VLOOKUP($AA$8,INPUT!$A$18:$D$24,4,FALSE),"") | AI8: =INPUT!$B$11 | AJ8: =INPUT!$B$12 | AK8: =INPUT!$B$13 | AL8: =INPUT!$B$14 | AM8: =INPUT!$B$15 | BD8: =IFERROR(VLOOKUP($P$8,INPUT!$A$48:$I$156,7,FALSE),"") | BE8: =IFERROR(VLOOKUP($P$8,INPUT!$A$48:$I$156,8,FALSE),"") | BF8: =IFERROR(VLOOKUP($P$8,INPUT!$A$48:$I$156,9,FALSE),"") | BG8: =IF(TRIM($Q$8)<>"",TRIM($Q$8),TRIM($R$8))
A9: =INPUT!$B$5 | B9: 04 | G9: =INPUT!$B$6 | H9: =IFERROR(VLOOKUP($P$9,INPUT!$A$48:$I$156,6,FALSE),"") | P9: wouldyourather_a0204 | Q9: =IFERROR(VLOOKUP($P$9,INPUT!$A$48:$I$156,4,FALSE),"") | R9: =IFERROR(VLOOKUP($P$9,INPUT!$A$48:$I$156,3,FALSE),"") | U9: ="<aside>🅰1️⃣"&$H$6&"<br><br>🅰2️⃣"&$H$7&"<br><br>🅱1️⃣"&$H$8&"<br><br><strong>🅱2️⃣"&$H$9&"</mark>" | Y9: =INPUT!$B$7 | Z9: =INPUT!$B$8 | AA9: =IFERROR(VLOOKUP($P$9,INPUT!$A$48:$I$156,5,FALSE),"") | AB9: =IFERROR(VLOOKUP($AA$9,INPUT!$A$18:$D$24,2,FALSE),"") | AC9: =INPUT!$B$9 | AF9: =IFERROR(VLOOKUP($AA$9,INPUT!$A$18:$D$24,3,FALSE),"") | AG9: =INPUT!$B$10 | AH9: =IFERROR(VLOOKUP($AA$9,INPUT!$A$18:$D$24,4,FALSE),"") | AI9: =INPUT!$B$11 | AJ9: =INPUT!$B$12 | AK9: =INPUT!$B$13 | AL9: =INPUT!$B$14 | AM9: =INPUT!$B$15 | BD9: =IFERROR(VLOOKUP($P$9,INPUT!$A$48:$I$156,7,FALSE),"") | BE9: =IFERROR(VLOOKUP($P$9,INPUT!$A$48:$I$156,8,FALSE),"") | BF9: =IFERROR(VLOOKUP($P$9,INPUT!$A$48:$I$156,9,FALSE),"") | BG9: =IF(TRIM($Q$9)<>"",TRIM($Q$9),TRIM($R$9))
A10: =INPUT!$B$5 | B10: 01 | G10: =INPUT!$B$6 | H10: =IFERROR(VLOOKUP($P$10,INPUT!$A$48:$I$156,6,FALSE),"") | P10: wouldyourather_a0301 | Q10: =IFERROR(VLOOKUP($P$10,INPUT!$A$48:$I$156,4,FALSE),"") | R10: =IFERROR(VLOOKUP($P$10,INPUT!$A$48:$I$156,3,FALSE),"") | U10: ="<aside><strong>🅰1️⃣"&$H$10&"</strong><br><br>🅰2️⃣___________<br><br>🅱1️⃣___________<br><br>🅱2️⃣___________></mark>" | Y10: =INPUT!$B$7 | Z10: =INPUT!$B$8 | AA10: =IFERROR(VLOOKUP($P$10,INPUT!$A$48:$I$156,5,FALSE),"") | AB10: =IFERROR(VLOOKUP($AA$10,INPUT!$A$18:$D$24,2,FALSE),"") | AC10: =INPUT!$B$9 | AF10: =IFERROR(VLOOKUP($AA$10,INPUT!$A$18:$D$24,3,FALSE),"") | AG10: =INPUT!$B$10 | AH10: =IFERROR(VLOOKUP($AA$10,INPUT!$A$18:$D$24,4,FALSE),"") | AI10: =INPUT!$B$11 | AJ10: =INPUT!$B$12 | AK10: =INPUT!$B$13 | AL10: =INPUT!$B$14 | AM10: =INPUT!$B$15 | BD10: =IFERROR(VLOOKUP($P$10,INPUT!$A$48:$I$156,7,FALSE),"") | BE10: =IFERROR(VLOOKUP($P$10,INPUT!$A$48:$I$156,8,FALSE),"") | BF10: =IFERROR(VLOOKUP($P$10,INPUT!$A$48:$I$156,9,FALSE),"") | BG10: =IF(TRIM($Q$10)<>"",TRIM($Q$10),TRIM($R$10))
A11: =INPUT!$B$5 | B11: 02 | G11: =INPUT!$B$6 | H11: =IFERROR(VLOOKUP($P$11,INPUT!$A$48:$I$156,6,FALSE),"") | P11: wouldyourather_a0302 | Q11: =IFERROR(VLOOKUP($P$11,INPUT!$A$48:$I$156,4,FALSE),"") | R11: =IFERROR(VLOOKUP($P$11,INPUT!$A$48:$I$156,3,FALSE),"") | U11: ="<aside>🅰1️⃣"&$H$10&"<br><br><strong>🅰2️⃣"&$H$11&"</strong><br><br>🅱1️⃣___________<br><br>🅱2️⃣___________</mark>" | Y11: =INPUT!$B$7 | Z11: =INPUT!$B$8 | AA11: =IFERROR(VLOOKUP($P$11,INPUT!$A$48:$I$156,5,FALSE),"") | AB11: =IFERROR(VLOOKUP($AA$11,INPUT!$A$18:$D$24,2,FALSE),"") | AC11: =INPUT!$B$9 | AF11: =IFERROR(VLOOKUP($AA$11,INPUT!$A$18:$D$24,3,FALSE),"") | AG11: =INPUT!$B$10 | AH11: =IFERROR(VLOOKUP($AA$11,INPUT!$A$18:$D$24,4,FALSE),"") | AI11: =INPUT!$B$11 | AJ11: =INPUT!$B$12 | AK11: =INPUT!$B$13 | AL11: =INPUT!$B$14 | AM11: =INPUT!$B$15 | BD11: =IFERROR(VLOOKUP($P$11,INPUT!$A$48:$I$156,7,FALSE),"") | BE11: =IFERROR(VLOOKUP($P$11,INPUT!$A$48:$I$156,8,FALSE),"") | BF11: =IFERROR(VLOOKUP($P$11,INPUT!$A$48:$I$156,9,FALSE),"") | BG11: =IF(TRIM($Q$11)<>"",TRIM($Q$11),TRIM($R$11))
A12: =INPUT!$B$5 | B12: 03 | G12: =INPUT!$B$6 | H12: =IFERROR(VLOOKUP($P$12,INPUT!$A$48:$I$156,6,FALSE),"") | P12: wouldyourather_a0303 | Q12: =IFERROR(VLOOKUP($P$12,INPUT!$A$48:$I$156,4,FALSE),"") | R12: =IFERROR(VLOOKUP($P$12,INPUT!$A$48:$I$156,3,FALSE),"") | U12: ="<aside>🅰1️⃣"&$H$10&"<br><br>🅰2️⃣"&$H$11&"<br><br><strong>🅱1️⃣"&$H$12&"</strong><br><br>🅱2️⃣___________</mark>" | Y12: =INPUT!$B$7 | Z12: =INPUT!$B$8 | AA12: =IFERROR(VLOOKUP($P$12,INPUT!$A$48:$I$156,5,FALSE),"") | AB12: =IFERROR(VLOOKUP($AA$12,INPUT!$A$18:$D$24,2,FALSE),"") | AC12: =INPUT!$B$9 | AF12: =IFERROR(VLOOKUP($AA$12,INPUT!$A$18:$D$24,3,FALSE),"") | AG12: =INPUT!$B$10 | AH12: =IFERROR(VLOOKUP($AA$12,INPUT!$A$18:$D$24,4,FALSE),"") | AI12: =INPUT!$B$11 | AJ12: =INPUT!$B$12 | AK12: =INPUT!$B$13 | AL12: =INPUT!$B$14 | AM12: =INPUT!$B$15 | BD12: =IFERROR(VLOOKUP($P$12,INPUT!$A$48:$I$156,7,FALSE),"") | BE12: =IFERROR(VLOOKUP($P$12,INPUT!$A$48:$I$156,8,FALSE),"") | BF12: =IFERROR(VLOOKUP($P$12,INPUT!$A$48:$I$156,9,FALSE),"") | BG12: =IF(TRIM($Q$12)<>"",TRIM($Q$12),TRIM($R$12))
A13: =INPUT!$B$5 | B13: 04 | G13: =INPUT!$B$6 | H13: =IFERROR(VLOOKUP($P$13,INPUT!$A$48:$I$156,6,FALSE),"") | P13: wouldyourather_a0304 | Q13: =IFERROR(VLOOKUP($P$13,INPUT!$A$48:$I$156,4,FALSE),"") | R13: =IFERROR(VLOOKUP($P$13,INPUT!$A$48:$I$156,3,FALSE),"") | U13: ="<aside>🅰1️⃣"&$H$10&"<br><br>🅰2️⃣"&$H$11&"<br><br>🅱1️⃣"&$H$12&"<br><br><strong>🅱2️⃣"&$H$13&"</mark>" | Y13: =INPUT!$B$7 | Z13: =INPUT!$B$8 | AA13: =IFERROR(VLOOKUP($P$13,INPUT!$A$48:$I$156,5,FALSE),"") | AB13: =IFERROR(VLOOKUP($AA$13,INPUT!$A$18:$D$24,2,FALSE),"") | AC13: =INPUT!$B$9 | AF13: =IFERROR(VLOOKUP($AA$13,INPUT!$A$18:$D$24,3,FALSE),"") | AG13: =INPUT!$B$10 | AH13: =IFERROR(VLOOKUP($AA$13,INPUT!$A$18:$D$24,4,FALSE),"") | AI13: =INPUT!$B$11 | AJ13: =INPUT!$B$12 | AK13: =INPUT!$B$13 | AL13: =INPUT!$B$14 | AM13: =INPUT!$B$15 | BD13: =IFERROR(VLOOKUP($P$13,INPUT!$A$48:$I$156,7,FALSE),"") | BE13: =IFERROR(VLOOKUP($P$13,INPUT!$A$48:$I$156,8,FALSE),"") | BF13: =IFERROR(VLOOKUP($P$13,INPUT!$A$48:$I$156,9,FALSE),"") | BG13: =IF(TRIM($Q$13)<>"",TRIM($Q$13),TRIM($R$13))
A14: =INPUT!$B$5 | B14: 01 | G14: =INPUT!$B$6 | H14: =IFERROR(VLOOKUP($P$14,INPUT!$A$48:$I$156,6,FALSE),"") | P14: wouldyourather_b01_i01 | Q14: =IFERROR(VLOOKUP($P$14,INPUT!$A$48:$I$156,4,FALSE),"") | R14: =IFERROR(VLOOKUP($P$14,INPUT!$A$48:$I$156,3,FALSE),"") | U14: ="<aside><strong>🅰1️⃣"&$H$14&"</strong><br><br>🅰2️⃣___________<br><br>🅱1️⃣___________<br><br>🅱2️⃣___________></mark>" | Y14: =INPUT!$B$7 | Z14: =INPUT!$B$8 | AA14: =IFERROR(VLOOKUP($P$14,INPUT!$A$48:$I$156,5,FALSE),"") | AB14: =IFERROR(VLOOKUP($AA$14,INPUT!$A$18:$D$24,2,FALSE),"") | AC14: =INPUT!$B$9 | AF14: =IFERROR(VLOOKUP($AA$14,INPUT!$A$18:$D$24,3,FALSE),"") | AG14: =INPUT!$B$10 | AH14: =IFERROR(VLOOKUP($AA$14,INPUT!$A$18:$D$24,4,FALSE),"") | AI14: =INPUT!$B$11 | AJ14: =INPUT!$B$12 | AK14: =INPUT!$B$13 | AL14: =INPUT!$B$14 | AM14: =INPUT!$B$15 | BD14: =IFERROR(VLOOKUP($P$14,INPUT!$A$48:$I$156,7,FALSE),"") | BE14: =IFERROR(VLOOKUP($P$14,INPUT!$A$48:$I$156,8,FALSE),"") | BF14: =IFERROR(VLOOKUP($P$14,INPUT!$A$48:$I$156,9,FALSE),"") | BG14: =IF(TRIM($Q$14)<>"",TRIM($Q$14),TRIM($R$14))
A15: =INPUT!$B$5 | B15: 02 | G15: =INPUT!$B$6 | H15: =IFERROR(VLOOKUP($P$15,INPUT!$A$48:$I$156,6,FALSE),"") | P15: wouldyourather_b01_i02 | Q15: =IFERROR(VLOOKUP($P$15,INPUT!$A$48:$I$156,4,FALSE),"") | R15: =IFERROR(VLOOKUP($P$15,INPUT!$A$48:$I$156,3,FALSE),"") | U15: ="<aside>🅰1️⃣"&$H$14&"<br><br><strong>🅰2️⃣"&$H$15&"</strong><br><br>🅱1️⃣___________<br><br>🅱2️⃣___________</mark>" | Y15: =INPUT!$B$7 | Z15: =INPUT!$B$8 | AA15: =IFERROR(VLOOKUP($P$15,INPUT!$A$48:$I$156,5,FALSE),"") | AB15: =IFERROR(VLOOKUP($AA$15,INPUT!$A$18:$D$24,2,FALSE),"") | AC15: =INPUT!$B$9 | AF15: =IFERROR(VLOOKUP($AA$15,INPUT!$A$18:$D$24,3,FALSE),"") | AG15: =INPUT!$B$10 | AH15: =IFERROR(VLOOKUP($AA$15,INPUT!$A$18:$D$24,4,FALSE),"") | AI15: =INPUT!$B$11 | AJ15: =INPUT!$B$12 | AK15: =INPUT!$B$13 | AL15: =INPUT!$B$14 | AM15: =INPUT!$B$15 | BD15: =IFERROR(VLOOKUP($P$15,INPUT!$A$48:$I$156,7,FALSE),"") | BE15: =IFERROR(VLOOKUP($P$15,INPUT!$A$48:$I$156,8,FALSE),"") | BF15: =IFERROR(VLOOKUP($P$15,INPUT!$A$48:$I$156,9,FALSE),"") | BG15: =IF(TRIM($Q$15)<>"",TRIM($Q$15),TRIM($R$15))
A16: =INPUT!$B$5 | B16: 03 | G16: =INPUT!$B$6 | H16: =IFERROR(VLOOKUP($P$16,INPUT!$A$48:$I$156,6,FALSE),"") | P16: wouldyourather_b01_i03 | Q16: =IFERROR(VLOOKUP($P$16,INPUT!$A$48:$I$156,4,FALSE),"") | R16: =IFERROR(VLOOKUP($P$16,INPUT!$A$48:$I$156,3,FALSE),"") | U16: ="<aside>🅰1️⃣"&$H$14&"<br><br>🅰2️⃣"&$H$15&"<br><br><strong>🅱1️⃣"&$H$16&"</strong><br><br>🅱2️⃣___________</mark>" | Y16: =INPUT!$B$7 | Z16: =INPUT!$B$8 | AA16: =IFERROR(VLOOKUP($P$16,INPUT!$A$48:$I$156,5,FALSE),"") | AB16: =IFERROR(VLOOKUP($AA$16,INPUT!$A$18:$D$24,2,FALSE),"") | AC16: =INPUT!$B$9 | AF16: =IFERROR(VLOOKUP($AA$16,INPUT!$A$18:$D$24,3,FALSE),"") | AG16: =INPUT!$B$10 | AH16: =IFERROR(VLOOKUP($AA$16,INPUT!$A$18:$D$24,4,FALSE),"") | AI16: =INPUT!$B$11 | AJ16: =INPUT!$B$12 | AK16: =INPUT!$B$13 | AL16: =INPUT!$B$14 | AM16: =INPUT!$B$15 | BD16: =IFERROR(VLOOKUP($P$16,INPUT!$A$48:$I$156,7,FALSE),"") | BE16: =IFERROR(VLOOKUP($P$16,INPUT!$A$48:$I$156,8,FALSE),"") | BF16: =IFERROR(VLOOKUP($P$16,INPUT!$A$48:$I$156,9,FALSE),"") | BG16: =IF(TRIM($Q$16)<>"",TRIM($Q$16),TRIM($R$16))
A17: =INPUT!$B$5 | B17: 04 | G17: =INPUT!$B$6 | H17: =IFERROR(VLOOKUP($P$17,INPUT!$A$48:$I$156,6,FALSE),"") | P17: wouldyourather_b01_i04 | Q17: =IFERROR(VLOOKUP($P$17,INPUT!$A$48:$I$156,4,FALSE),"") | R17: =IFERROR(VLOOKUP($P$17,INPUT!$A$48:$I$156,3,FALSE),"") | U17: ="<aside>🅰1️⃣"&$H$14&"<br><br>🅰2️⃣"&$H$15&"<br><br>🅱1️⃣"&$H$16&"<br><br><strong>🅱2️⃣"&$H$17&"</mark>" | Y17: =INPUT!$B$7 | Z17: =INPUT!$B$8 | AA17: =IFERROR(VLOOKUP($P$17,INPUT!$A$48:$I$156,5,FALSE),"") | AB17: =IFERROR(VLOOKUP($AA$17,INPUT!$A$18:$D$24,2,FALSE),"") | AC17: =INPUT!$B$9 | AF17: =IFERROR(VLOOKUP($AA$17,INPUT!$A$18:$D$24,3,FALSE),"") | AG17: =INPUT!$B$10 | AH17: =IFERROR(VLOOKUP($AA$17,INPUT!$A$18:$D$24,4,FALSE),"") | AI17: =INPUT!$B$11 | AJ17: =INPUT!$B$12 | AK17: =INPUT!$B$13 | AL17: =INPUT!$B$14 | AM17: =INPUT!$B$15 | BD17: =IFERROR(VLOOKUP($P$17,INPUT!$A$48:$I$156,7,FALSE),"") | BE17: =IFERROR(VLOOKUP($P$17,INPUT!$A$48:$I$156,8,FALSE),"") | BF17: =IFERROR(VLOOKUP($P$17,INPUT!$A$48:$I$156,9,FALSE),"") | BG17: =IF(TRIM($Q$17)<>"",TRIM($Q$17),TRIM($R$17))
A18: =INPUT!$B$5 | B18: 01 | G18: =INPUT!$B$6 | H18: =IFERROR(VLOOKUP($P$18,INPUT!$A$48:$I$156,6,FALSE),"") | P18: wouldyourather_b01_ii01 | Q18: =IFERROR(VLOOKUP($P$18,INPUT!$A$48:$I$156,4,FALSE),"") | R18: =IFERROR(VLOOKUP($P$18,INPUT!$A$48:$I$156,3,FALSE),"") | U18: ="<aside><strong>🅰1️⃣"&$H$18&"</strong><br><br>🅰2️⃣___________<br><br>🅱1️⃣___________<br><br>🅱2️⃣___________></mark>" | Y18: =INPUT!$B$7 | Z18: =INPUT!$B$8 | AA18: =IFERROR(VLOOKUP($P$18,INPUT!$A$48:$I$156,5,FALSE),"") | AB18: =IFERROR(VLOOKUP($AA$18,INPUT!$A$18:$D$24,2,FALSE),"") | AC18: =INPUT!$B$9 | AF18: =IFERROR(VLOOKUP($AA$18,INPUT!$A$18:$D$24,3,FALSE),"") | AG18: =INPUT!$B$10 | AH18: =IFERROR(VLOOKUP($AA$18,INPUT!$A$18:$D$24,4,FALSE),"") | AI18: =INPUT!$B$11 | AJ18: =INPUT!$B$12 | AK18: =INPUT!$B$13 | AL18: =INPUT!$B$14 | AM18: =INPUT!$B$15 | BD18: =IFERROR(VLOOKUP($P$18,INPUT!$A$48:$I$156,7,FALSE),"") | BE18: =IFERROR(VLOOKUP($P$18,INPUT!$A$48:$I$156,8,FALSE),"") | BF18: =IFERROR(VLOOKUP($P$18,INPUT!$A$48:$I$156,9,FALSE),"") | BG18: =IF(TRIM($Q$18)<>"",TRIM($Q$18),TRIM($R$18))
A19: =INPUT!$B$5 | B19: 02 | G19: =INPUT!$B$6 | H19: =IFERROR(VLOOKUP($P$19,INPUT!$A$48:$I$156,6,FALSE),"") | P19: wouldyourather_b01_ii02 | Q19: =IFERROR(VLOOKUP($P$19,INPUT!$A$48:$I$156,4,FALSE),"") | R19: =IFERROR(VLOOKUP($P$19,INPUT!$A$48:$I$156,3,FALSE),"") | U19: ="<aside>🅰1️⃣"&$H$18&"<br><br><strong>🅰2️⃣"&$H$19&"</strong><br><br>🅱1️⃣___________<br><br>🅱2️⃣___________</mark>" | Y19: =INPUT!$B$7 | Z19: =INPUT!$B$8 | AA19: =IFERROR(VLOOKUP($P$19,INPUT!$A$48:$I$156,5,FALSE),"") | AB19: =IFERROR(VLOOKUP($AA$19,INPUT!$A$18:$D$24,2,FALSE),"") | AC19: =INPUT!$B$9 | AF19: =IFERROR(VLOOKUP($AA$19,INPUT!$A$18:$D$24,3,FALSE),"") | AG19: =INPUT!$B$10 | AH19: =IFERROR(VLOOKUP($AA$19,INPUT!$A$18:$D$24,4,FALSE),"") | AI19: =INPUT!$B$11 | AJ19: =INPUT!$B$12 | AK19: =INPUT!$B$13 | AL19: =INPUT!$B$14 | AM19: =INPUT!$B$15 | BD19: =IFERROR(VLOOKUP($P$19,INPUT!$A$48:$I$156,7,FALSE),"") | BE19: =IFERROR(VLOOKUP($P$19,INPUT!$A$48:$I$156,8,FALSE),"") | BF19: =IFERROR(VLOOKUP($P$19,INPUT!$A$48:$I$156,9,FALSE),"") | BG19: =IF(TRIM($Q$19)<>"",TRIM($Q$19),TRIM($R$19))
A20: =INPUT!$B$5 | B20: 03 | G20: =INPUT!$B$6 | H20: =IFERROR(VLOOKUP($P$20,INPUT!$A$48:$I$156,6,FALSE),"") | P20: wouldyourather_b01_ii03 | Q20: =IFERROR(VLOOKUP($P$20,INPUT!$A$48:$I$156,4,FALSE),"") | R20: =IFERROR(VLOOKUP($P$20,INPUT!$A$48:$I$156,3,FALSE),"") | U20: ="<aside>🅰1️⃣"&$H$18&"<br><br>🅰2️⃣"&$H$19&"<br><br><strong>🅱1️⃣"&$H$20&"</strong><br><br>🅱2️⃣___________</mark>" | Y20: =INPUT!$B$7 | Z20: =INPUT!$B$8 | AA20: =IFERROR(VLOOKUP($P$20,INPUT!$A$48:$I$156,5,FALSE),"") | AB20: =IFERROR(VLOOKUP($AA$20,INPUT!$A$18:$D$24,2,FALSE),"") | AC20: =INPUT!$B$9 | AF20: =IFERROR(VLOOKUP($AA$20,INPUT!$A$18:$D$24,3,FALSE),"") | AG20: =INPUT!$B$10 | AH20: =IFERROR(VLOOKUP($AA$20,INPUT!$A$18:$D$24,4,FALSE),"") | AI20: =INPUT!$B$11 | AJ20: =INPUT!$B$12 | AK20: =INPUT!$B$13 | AL20: =INPUT!$B$14 | AM20: =INPUT!$B$15 | BD20: =IFERROR(VLOOKUP($P$20,INPUT!$A$48:$I$156,7,FALSE),"") | BE20: =IFERROR(VLOOKUP($P$20,INPUT!$A$48:$I$156,8,FALSE),"") | BF20: =IFERROR(VLOOKUP($P$20,INPUT!$A$48:$I$156,9,FALSE),"") | BG20: =IF(TRIM($Q$20)<>"",TRIM($Q$20),TRIM($R$20))
A21: =INPUT!$B$5 | B21: 04 | G21: =INPUT!$B$6 | H21: =IFERROR(VLOOKUP($P$21,INPUT!$A$48:$I$156,6,FALSE),"") | P21: wouldyourather_b01_ii04 | Q21: =IFERROR(VLOOKUP($P$21,INPUT!$A$48:$I$156,4,FALSE),"") | R21: =IFERROR(VLOOKUP($P$21,INPUT!$A$48:$I$156,3,FALSE),"") | U21: ="<aside>🅰1️⃣"&$H$18&"<br><br>🅰2️⃣"&$H$19&"<br><br>🅱1️⃣"&$H$20&"<br><br><strong>🅱2️⃣"&$H$21&"</mark>" | Y21: =INPUT!$B$7 | Z21: =INPUT!$B$8 | AA21: =IFERROR(VLOOKUP($P$21,INPUT!$A$48:$I$156,5,FALSE),"") | AB21: =IFERROR(VLOOKUP($AA$21,INPUT!$A$18:$D$24,2,FALSE),"") | AC21: =INPUT!$B$9 | AF21: =IFERROR(VLOOKUP($AA$21,INPUT!$A$18:$D$24,3,FALSE),"") | AG21: =INPUT!$B$10 | AH21: =IFERROR(VLOOKUP($AA$21,INPUT!$A$18:$D$24,4,FALSE),"") | AI21: =INPUT!$B$11 | AJ21: =INPUT!$B$12 | AK21: =INPUT!$B$13 | AL21: =INPUT!$B$14 | AM21: =INPUT!$B$15 | BD21: =IFERROR(VLOOKUP($P$21,INPUT!$A$48:$I$156,7,FALSE),"") | BE21: =IFERROR(VLOOKUP($P$21,INPUT!$A$48:$I$156,8,FALSE),"") | BF21: =IFERROR(VLOOKUP($P$21,INPUT!$A$48:$I$156,9,FALSE),"") | BG21: =IF(TRIM($Q$21)<>"",TRIM($Q$21),TRIM($R$21))
A22: =INPUT!$B$5 | B22: 01 | G22: =INPUT!$B$6 | H22: =IFERROR(VLOOKUP($P$22,INPUT!$A$48:$I$156,6,FALSE),"") | P22: wouldyourather_b02_i01 | Q22: =IFERROR(VLOOKUP($P$22,INPUT!$A$48:$I$156,4,FALSE),"") | R22: =IFERROR(VLOOKUP($P$22,INPUT!$A$48:$I$156,3,FALSE),"") | U22: ="<aside><strong>🅰1️⃣"&$H$22&"</strong><br><br>🅰2️⃣___________<br><br>🅱1️⃣___________<br><br>🅱2️⃣___________></mark>" | Y22: =INPUT!$B$7 | Z22: =INPUT!$B$8 | AA22: =IFERROR(VLOOKUP($P$22,INPUT!$A$48:$I$156,5,FALSE),"") | AB22: =IFERROR(VLOOKUP($AA$22,INPUT!$A$18:$D$24,2,FALSE),"") | AC22: =INPUT!$B$9 | AF22: =IFERROR(VLOOKUP($AA$22,INPUT!$A$18:$D$24,3,FALSE),"") | AG22: =INPUT!$B$10 | AH22: =IFERROR(VLOOKUP($AA$22,INPUT!$A$18:$D$24,4,FALSE),"") | AI22: =INPUT!$B$11 | AJ22: =INPUT!$B$12 | AK22: =INPUT!$B$13 | AL22: =INPUT!$B$14 | AM22: =INPUT!$B$15 | BD22: =IFERROR(VLOOKUP($P$22,INPUT!$A$48:$I$156,7,FALSE),"") | BE22: =IFERROR(VLOOKUP($P$22,INPUT!$A$48:$I$156,8,FALSE),"") | BF22: =IFERROR(VLOOKUP($P$22,INPUT!$A$48:$I$156,9,FALSE),"") | BG22: =IF(TRIM($Q$22)<>"",TRIM($Q$22),TRIM($R$22))
A23: =INPUT!$B$5 | B23: 02 | G23: =INPUT!$B$6 | H23: =IFERROR(VLOOKUP($P$23,INPUT!$A$48:$I$156,6,FALSE),"") | P23: wouldyourather_b02_i02 | Q23: =IFERROR(VLOOKUP($P$23,INPUT!$A$48:$I$156,4,FALSE),"") | R23: =IFERROR(VLOOKUP($P$23,INPUT!$A$48:$I$156,3,FALSE),"") | U23: ="<aside>🅰1️⃣"&$H$22&"<br><br><strong>🅰2️⃣"&$H$23&"</strong><br><br>🅱1️⃣___________<br><br>🅱2️⃣___________</mark>" | Y23: =INPUT!$B$7 | Z23: =INPUT!$B$8 | AA23: =IFERROR(VLOOKUP($P$23,INPUT!$A$48:$I$156,5,FALSE),"") | AB23: =IFERROR(VLOOKUP($AA$23,INPUT!$A$18:$D$24,2,FALSE),"") | AC23: =INPUT!$B$9 | AF23: =IFERROR(VLOOKUP($AA$23,INPUT!$A$18:$D$24,3,FALSE),"") | AG23: =INPUT!$B$10 | AH23: =IFERROR(VLOOKUP($AA$23,INPUT!$A$18:$D$24,4,FALSE),"") | AI23: =INPUT!$B$11 | AJ23: =INPUT!$B$12 | AK23: =INPUT!$B$13 | AL23: =INPUT!$B$14 | AM23: =INPUT!$B$15 | BD23: =IFERROR(VLOOKUP($P$23,INPUT!$A$48:$I$156,7,FALSE),"") | BE23: =IFERROR(VLOOKUP($P$23,INPUT!$A$48:$I$156,8,FALSE),"") | BF23: =IFERROR(VLOOKUP($P$23,INPUT!$A$48:$I$156,9,FALSE),"") | BG23: =IF(TRIM($Q$23)<>"",TRIM($Q$23),TRIM($R$23))
A24: =INPUT!$B$5 | B24: 03 | G24: =INPUT!$B$6 | H24: =IFERROR(VLOOKUP($P$24,INPUT!$A$48:$I$156,6,FALSE),"") | P24: wouldyourather_b02_i03 | Q24: =IFERROR(VLOOKUP($P$24,INPUT!$A$48:$I$156,4,FALSE),"") | R24: =IFERROR(VLOOKUP($P$24,INPUT!$A$48:$I$156,3,FALSE),"") | U24: ="<aside>🅰1️⃣"&$H$22&"<br><br>🅰2️⃣"&$H$23&"<br><br><strong>🅱1️⃣"&$H$24&"</strong><br><br>🅱2️⃣___________</mark>" | Y24: =INPUT!$B$7 | Z24: =INPUT!$B$8 | AA24: =IFERROR(VLOOKUP($P$24,INPUT!$A$48:$I$156,5,FALSE),"") | AB24: =IFERROR(VLOOKUP($AA$24,INPUT!$A$18:$D$24,2,FALSE),"") | AC24: =INPUT!$B$9 | AF24: =IFERROR(VLOOKUP($AA$24,INPUT!$A$18:$D$24,3,FALSE),"") | AG24: =INPUT!$B$10 | AH24: =IFERROR(VLOOKUP($AA$24,INPUT!$A$18:$D$24,4,FALSE),"") | AI24: =INPUT!$B$11 | AJ24: =INPUT!$B$12 | AK24: =INPUT!$B$13 | AL24: =INPUT!$B$14 | AM24: =INPUT!$B$15 | BD24: =IFERROR(VLOOKUP($P$24,INPUT!$A$48:$I$156,7,FALSE),"") | BE24: =IFERROR(VLOOKUP($P$24,INPUT!$A$48:$I$156,8,FALSE),"") | BF24: =IFERROR(VLOOKUP($P$24,INPUT!$A$48:$I$156,9,FALSE),"") | BG24: =IF(TRIM($Q$24)<>"",TRIM($Q$24),TRIM($R$24))
A25: =INPUT!$B$5 | B25: 04 | G25: =INPUT!$B$6 | H25: =IFERROR(VLOOKUP($P$25,INPUT!$A$48:$I$156,6,FALSE),"") | P25: wouldyourather_b02_i04 | Q25: =IFERROR(VLOOKUP($P$25,INPUT!$A$48:$I$156,4,FALSE),"") | R25: =IFERROR(VLOOKUP($P$25,INPUT!$A$48:$I$156,3,FALSE),"") | U25: ="<aside>🅰1️⃣"&$H$22&"<br><br>🅰2️⃣"&$H$23&"<br><br>🅱1️⃣"&$H$24&"<br><br><strong>🅱2️⃣"&$H$25&"</mark>" | Y25: =INPUT!$B$7 | Z25: =INPUT!$B$8 | AA25: =IFERROR(VLOOKUP($P$25,INPUT!$A$48:$I$156,5,FALSE),"") | AB25: =IFERROR(VLOOKUP($AA$25,INPUT!$A$18:$D$24,2,FALSE),"") | AC25: =INPUT!$B$9 | AF25: =IFERROR(VLOOKUP($AA$25,INPUT!$A$18:$D$24,3,FALSE),"") | AG25: =INPUT!$B$10 | AH25: =IFERROR(VLOOKUP($AA$25,INPUT!$A$18:$D$24,4,FALSE),"") | AI25: =INPUT!$B$11 | AJ25: =INPUT!$B$12 | AK25: =INPUT!$B$13 | AL25: =INPUT!$B$14 | AM25: =INPUT!$B$15 | BD25: =IFERROR(VLOOKUP($P$25,INPUT!$A$48:$I$156,7,FALSE),"") | BE25: =IFERROR(VLOOKUP($P$25,INPUT!$A$48:$I$156,8,FALSE),"") | BF25: =IFERROR(VLOOKUP($P$25,INPUT!$A$48:$I$156,9,FALSE),"") | BG25: =IF(TRIM($Q$25)<>"",TRIM($Q$25),TRIM($R$25))
A26: =INPUT!$B$5 | B26: 01 | G26: =INPUT!$B$6 | H26: =IFERROR(VLOOKUP($P$26,INPUT!$A$48:$I$156,6,FALSE),"") | P26: wouldyourather_b02_ii01 | Q26: =IFERROR(VLOOKUP($P$26,INPUT!$A$48:$I$156,4,FALSE),"") | R26: =IFERROR(VLOOKUP($P$26,INPUT!$A$48:$I$156,3,FALSE),"") | U26: ="<aside><strong>🅰1️⃣"&$H$26&"</strong><br><br>🅰2️⃣___________<br><br>🅱1️⃣___________<br><br>🅱2️⃣___________></mark>" | Y26: =INPUT!$B$7 | Z26: =INPUT!$B$8 | AA26: =IFERROR(VLOOKUP($P$26,INPUT!$A$48:$I$156,5,FALSE),"") | AB26: =IFERROR(VLOOKUP($AA$26,INPUT!$A$18:$D$24,2,FALSE),"") | AC26: =INPUT!$B$9 | AF26: =IFERROR(VLOOKUP($AA$26,INPUT!$A$18:$D$24,3,FALSE),"") | AG26: =INPUT!$B$10 | AH26: =IFERROR(VLOOKUP($AA$26,INPUT!$A$18:$D$24,4,FALSE),"") | AI26: =INPUT!$B$11 | AJ26: =INPUT!$B$12 | AK26: =INPUT!$B$13 | AL26: =INPUT!$B$14 | AM26: =INPUT!$B$15 | BD26: =IFERROR(VLOOKUP($P$26,INPUT!$A$48:$I$156,7,FALSE),"") | BE26: =IFERROR(VLOOKUP($P$26,INPUT!$A$48:$I$156,8,FALSE),"") | BF26: =IFERROR(VLOOKUP($P$26,INPUT!$A$48:$I$156,9,FALSE),"") | BG26: =IF(TRIM($Q$26)<>"",TRIM($Q$26),TRIM($R$26))
A27: =INPUT!$B$5 | B27: 02 | G27: =INPUT!$B$6 | H27: =IFERROR(VLOOKUP($P$27,INPUT!$A$48:$I$156,6,FALSE),"") | P27: wouldyourather_b02_ii02 | Q27: =IFERROR(VLOOKUP($P$27,INPUT!$A$48:$I$156,4,FALSE),"") | R27: =IFERROR(VLOOKUP($P$27,INPUT!$A$48:$I$156,3,FALSE),"") | U27: ="<aside>🅰1️⃣"&$H$26&"<br><br><strong>🅰2️⃣"&$H$27&"</strong><br><br>🅱1️⃣___________<br><br>🅱2️⃣___________</mark>" | Y27: =INPUT!$B$7 | Z27: =INPUT!$B$8 | AA27: =IFERROR(VLOOKUP($P$27,INPUT!$A$48:$I$156,5,FALSE),"") | AB27: =IFERROR(VLOOKUP($AA$27,INPUT!$A$18:$D$24,2,FALSE),"") | AC27: =INPUT!$B$9 | AF27: =IFERROR(VLOOKUP($AA$27,INPUT!$A$18:$D$24,3,FALSE),"") | AG27: =INPUT!$B$10 | AH27: =IFERROR(VLOOKUP($AA$27,INPUT!$A$18:$D$24,4,FALSE),"") | AI27: =INPUT!$B$11 | AJ27: =INPUT!$B$12 | AK27: =INPUT!$B$13 | AL27: =INPUT!$B$14 | AM27: =INPUT!$B$15 | BD27: =IFERROR(VLOOKUP($P$27,INPUT!$A$48:$I$156,7,FALSE),"") | BE27: =IFERROR(VLOOKUP($P$27,INPUT!$A$48:$I$156,8,FALSE),"") | BF27: =IFERROR(VLOOKUP($P$27,INPUT!$A$48:$I$156,9,FALSE),"") | BG27: =IF(TRIM($Q$27)<>"",TRIM($Q$27),TRIM($R$27))
A28: =INPUT!$B$5 | B28: 03 | G28: =INPUT!$B$6 | H28: =IFERROR(VLOOKUP($P$28,INPUT!$A$48:$I$156,6,FALSE),"") | P28: wouldyourather_b02_ii03 | Q28: =IFERROR(VLOOKUP($P$28,INPUT!$A$48:$I$156,4,FALSE),"") | R28: =IFERROR(VLOOKUP($P$28,INPUT!$A$48:$I$156,3,FALSE),"") | U28: ="<aside>🅰1️⃣"&$H$26&"<br><br>🅰2️⃣"&$H$27&"<br><br><strong>🅱1️⃣"&$H$28&"</strong><br><br>🅱2️⃣___________</mark>" | Y28: =INPUT!$B$7 | Z28: =INPUT!$B$8 | AA28: =IFERROR(VLOOKUP($P$28,INPUT!$A$48:$I$156,5,FALSE),"") | AB28: =IFERROR(VLOOKUP($AA$28,INPUT!$A$18:$D$24,2,FALSE),"") | AC28: =INPUT!$B$9 | AF28: =IFERROR(VLOOKUP($AA$28,INPUT!$A$18:$D$24,3,FALSE),"") | AG28: =INPUT!$B$10 | AH28: =IFERROR(VLOOKUP($AA$28,INPUT!$A$18:$D$24,4,FALSE),"") | AI28: =INPUT!$B$11 | AJ28: =INPUT!$B$12 | AK28: =INPUT!$B$13 | AL28: =INPUT!$B$14 | AM28: =INPUT!$B$15 | BD28: =IFERROR(VLOOKUP($P$28,INPUT!$A$48:$I$156,7,FALSE),"") | BE28: =IFERROR(VLOOKUP($P$28,INPUT!$A$48:$I$156,8,FALSE),"") | BF28: =IFERROR(VLOOKUP($P$28,INPUT!$A$48:$I$156,9,FALSE),"") | BG28: =IF(TRIM($Q$28)<>"",TRIM($Q$28),TRIM($R$28))
A29: =INPUT!$B$5 | B29: 04 | G29: =INPUT!$B$6 | H29: =IFERROR(VLOOKUP($P$29,INPUT!$A$48:$I$156,6,FALSE),"") | P29: wouldyourather_b02_ii04 | Q29: =IFERROR(VLOOKUP($P$29,INPUT!$A$48:$I$156,4,FALSE),"") | R29: =IFERROR(VLOOKUP($P$29,INPUT!$A$48:$I$156,3,FALSE),"") | U29: ="<aside>🅰1️⃣"&$H$26&"<br><br>🅰2️⃣"&$H$27&"<br><br>🅱1️⃣"&$H$28&"<br><br><strong>🅱2️⃣"&$H$29&"</mark>" | Y29: =INPUT!$B$7 | Z29: =INPUT!$B$8 | AA29: =IFERROR(VLOOKUP($P$29,INPUT!$A$48:$I$156,5,FALSE),"") | AB29: =IFERROR(VLOOKUP($AA$29,INPUT!$A$18:$D$24,2,FALSE),"") | AC29: =INPUT!$B$9 | AF29: =IFERROR(VLOOKUP($AA$29,INPUT!$A$18:$D$24,3,FALSE),"") | AG29: =INPUT!$B$10 | AH29: =IFERROR(VLOOKUP($AA$29,INPUT!$A$18:$D$24,4,FALSE),"") | AI29: =INPUT!$B$11 | AJ29: =INPUT!$B$12 | AK29: =INPUT!$B$13 | AL29: =INPUT!$B$14 | AM29: =INPUT!$B$15 | BD29: =IFERROR(VLOOKUP($P$29,INPUT!$A$48:$I$156,7,FALSE),"") | BE29: =IFERROR(VLOOKUP($P$29,INPUT!$A$48:$I$156,8,FALSE),"") | BF29: =IFERROR(VLOOKUP($P$29,INPUT!$A$48:$I$156,9,FALSE),"") | BG29: =IF(TRIM($Q$29)<>"",TRIM($Q$29),TRIM($R$29))
A30: =INPUT!$B$5 | B30: 01 | G30: =INPUT!$B$6 | H30: =IFERROR(VLOOKUP($P$30,INPUT!$A$48:$I$156,6,FALSE),"") | P30: wouldyourather_b03_i01 | Q30: =IFERROR(VLOOKUP($P$30,INPUT!$A$48:$I$156,4,FALSE),"") | R30: =IFERROR(VLOOKUP($P$30,INPUT!$A$48:$I$156,3,FALSE),"") | U30: ="<aside><strong>🅰1️⃣"&$H$30&"</strong><br><br>🅰2️⃣___________<br><br>🅱1️⃣___________<br><br>🅱2️⃣___________></mark>" | Y30: =INPUT!$B$7 | Z30: =INPUT!$B$8 | AA30: =IFERROR(VLOOKUP($P$30,INPUT!$A$48:$I$156,5,FALSE),"") | AB30: =IFERROR(VLOOKUP($AA$30,INPUT!$A$18:$D$24,2,FALSE),"") | AC30: =INPUT!$B$9 | AF30: =IFERROR(VLOOKUP($AA$30,INPUT!$A$18:$D$24,3,FALSE),"") | AG30: =INPUT!$B$10 | AH30: =IFERROR(VLOOKUP($AA$30,INPUT!$A$18:$D$24,4,FALSE),"") | AI30: =INPUT!$B$11 | AJ30: =INPUT!$B$12 | AK30: =INPUT!$B$13 | AL30: =INPUT!$B$14 | AM30: =INPUT!$B$15 | BD30: =IFERROR(VLOOKUP($P$30,INPUT!$A$48:$I$156,7,FALSE),"") | BE30: =IFERROR(VLOOKUP($P$30,INPUT!$A$48:$I$156,8,FALSE),"") | BF30: =IFERROR(VLOOKUP($P$30,INPUT!$A$48:$I$156,9,FALSE),"") | BG30: =IF(TRIM($Q$30)<>"",TRIM($Q$30),TRIM($R$30))
A31: =INPUT!$B$5 | B31: 02 | G31: =INPUT!$B$6 | H31: =IFERROR(VLOOKUP($P$31,INPUT!$A$48:$I$156,6,FALSE),"") | P31: wouldyourather_b03_i02 | Q31: =IFERROR(VLOOKUP($P$31,INPUT!$A$48:$I$156,4,FALSE),"") | R31: =IFERROR(VLOOKUP($P$31,INPUT!$A$48:$I$156,3,FALSE),"") | U31: ="<aside>🅰1️⃣"&$H$30&"<br><br><strong>🅰2️⃣"&$H$31&"</strong><br><br>🅱1️⃣___________<br><br>🅱2️⃣___________</mark>" | Y31: =INPUT!$B$7 | Z31: =INPUT!$B$8 | AA31: =IFERROR(VLOOKUP($P$31,INPUT!$A$48:$I$156,5,FALSE),"") | AB31: =IFERROR(VLOOKUP($AA$31,INPUT!$A$18:$D$24,2,FALSE),"") | AC31: =INPUT!$B$9 | AF31: =IFERROR(VLOOKUP($AA$31,INPUT!$A$18:$D$24,3,FALSE),"") | AG31: =INPUT!$B$10 | AH31: =IFERROR(VLOOKUP($AA$31,INPUT!$A$18:$D$24,4,FALSE),"") | AI31: =INPUT!$B$11 | AJ31: =INPUT!$B$12 | AK31: =INPUT!$B$13 | AL31: =INPUT!$B$14 | AM31: =INPUT!$B$15 | BD31: =IFERROR(VLOOKUP($P$31,INPUT!$A$48:$I$156,7,FALSE),"") | BE31: =IFERROR(VLOOKUP($P$31,INPUT!$A$48:$I$156,8,FALSE),"") | BF31: =IFERROR(VLOOKUP($P$31,INPUT!$A$48:$I$156,9,FALSE),"") | BG31: =IF(TRIM($Q$31)<>"",TRIM($Q$31),TRIM($R$31))
A32: =INPUT!$B$5 | B32: 03 | G32: =INPUT!$B$6 | H32: =IFERROR(VLOOKUP($P$32,INPUT!$A$48:$I$156,6,FALSE),"") | P32: wouldyourather_b03_i03 | Q32: =IFERROR(VLOOKUP($P$32,INPUT!$A$48:$I$156,4,FALSE),"") | R32: =IFERROR(VLOOKUP($P$32,INPUT!$A$48:$I$156,3,FALSE),"") | U32: ="<aside>🅰1️⃣"&$H$30&"<br><br>🅰2️⃣"&$H$31&"<br><br><strong>🅱1️⃣"&$H$32&"</strong><br><br>🅱2️⃣___________</mark>" | Y32: =INPUT!$B$7 | Z32: =INPUT!$B$8 | AA32: =IFERROR(VLOOKUP($P$32,INPUT!$A$48:$I$156,5,FALSE),"") | AB32: =IFERROR(VLOOKUP($AA$32,INPUT!$A$18:$D$24,2,FALSE),"") | AC32: =INPUT!$B$9 | AF32: =IFERROR(VLOOKUP($AA$32,INPUT!$A$18:$D$24,3,FALSE),"") | AG32: =INPUT!$B$10 | AH32: =IFERROR(VLOOKUP($AA$32,INPUT!$A$18:$D$24,4,FALSE),"") | AI32: =INPUT!$B$11 | AJ32: =INPUT!$B$12 | AK32: =INPUT!$B$13 | AL32: =INPUT!$B$14 | AM32: =INPUT!$B$15 | BD32: =IFERROR(VLOOKUP($P$32,INPUT!$A$48:$I$156,7,FALSE),"") | BE32: =IFERROR(VLOOKUP($P$32,INPUT!$A$48:$I$156,8,FALSE),"") | BF32: =IFERROR(VLOOKUP($P$32,INPUT!$A$48:$I$156,9,FALSE),"") | BG32: =IF(TRIM($Q$32)<>"",TRIM($Q$32),TRIM($R$32))
A33: =INPUT!$B$5 | B33: 04 | G33: =INPUT!$B$6 | H33: =IFERROR(VLOOKUP($P$33,INPUT!$A$48:$I$156,6,FALSE),"") | P33: wouldyourather_b03_i04 | Q33: =IFERROR(VLOOKUP($P$33,INPUT!$A$48:$I$156,4,FALSE),"") | R33: =IFERROR(VLOOKUP($P$33,INPUT!$A$48:$I$156,3,FALSE),"") | U33: ="<aside>🅰1️⃣"&$H$30&"<br><br>🅰2️⃣"&$H$31&"<br><br>🅱1️⃣"&$H$32&"<br><br><strong>🅱2️⃣"&$H$33&"</mark>" | Y33: =INPUT!$B$7 | Z33: =INPUT!$B$8 | AA33: =IFERROR(VLOOKUP($P$33,INPUT!$A$48:$I$156,5,FALSE),"") | AB33: =IFERROR(VLOOKUP($AA$33,INPUT!$A$18:$D$24,2,FALSE),"") | AC33: =INPUT!$B$9 | AF33: =IFERROR(VLOOKUP($AA$33,INPUT!$A$18:$D$24,3,FALSE),"") | AG33: =INPUT!$B$10 | AH33: =IFERROR(VLOOKUP($AA$33,INPUT!$A$18:$D$24,4,FALSE),"") | AI33: =INPUT!$B$11 | AJ33: =INPUT!$B$12 | AK33: =INPUT!$B$13 | AL33: =INPUT!$B$14 | AM33: =INPUT!$B$15 | BD33: =IFERROR(VLOOKUP($P$33,INPUT!$A$48:$I$156,7,FALSE),"") | BE33: =IFERROR(VLOOKUP($P$33,INPUT!$A$48:$I$156,8,FALSE),"") | BF33: =IFERROR(VLOOKUP($P$33,INPUT!$A$48:$I$156,9,FALSE),"") | BG33: =IF(TRIM($Q$33)<>"",TRIM($Q$33),TRIM($R$33))
A34: =INPUT!$B$5 | B34: 01 | G34: =INPUT!$B$6 | H34: =IFERROR(VLOOKUP($P$34,INPUT!$A$48:$I$156,6,FALSE),"") | P34: wouldyourather_b03_ii01 | Q34: =IFERROR(VLOOKUP($P$34,INPUT!$A$48:$I$156,4,FALSE),"") | R34: =IFERROR(VLOOKUP($P$34,INPUT!$A$48:$I$156,3,FALSE),"") | U34: ="<aside><strong>🅰1️⃣"&$H$34&"</strong><br><br>🅰2️⃣___________<br><br>🅱1️⃣___________<br><br>🅱2️⃣___________></mark>" | Y34: =INPUT!$B$7 | Z34: =INPUT!$B$8 | AA34: =IFERROR(VLOOKUP($P$34,INPUT!$A$48:$I$156,5,FALSE),"") | AB34: =IFERROR(VLOOKUP($AA$34,INPUT!$A$18:$D$24,2,FALSE),"") | AC34: =INPUT!$B$9 | AF34: =IFERROR(VLOOKUP($AA$34,INPUT!$A$18:$D$24,3,FALSE),"") | AG34: =INPUT!$B$10 | AH34: =IFERROR(VLOOKUP($AA$34,INPUT!$A$18:$D$24,4,FALSE),"") | AI34: =INPUT!$B$11 | AJ34: =INPUT!$B$12 | AK34: =INPUT!$B$13 | AL34: =INPUT!$B$14 | AM34: =INPUT!$B$15 | BD34: =IFERROR(VLOOKUP($P$34,INPUT!$A$48:$I$156,7,FALSE),"") | BE34: =IFERROR(VLOOKUP($P$34,INPUT!$A$48:$I$156,8,FALSE),"") | BF34: =IFERROR(VLOOKUP($P$34,INPUT!$A$48:$I$156,9,FALSE),"") | BG34: =IF(TRIM($Q$34)<>"",TRIM($Q$34),TRIM($R$34))
A35: =INPUT!$B$5 | B35: 02 | G35: =INPUT!$B$6 | H35: =IFERROR(VLOOKUP($P$35,INPUT!$A$48:$I$156,6,FALSE),"") | P35: wouldyourather_b03_ii02 | Q35: =IFERROR(VLOOKUP($P$35,INPUT!$A$48:$I$156,4,FALSE),"") | R35: =IFERROR(VLOOKUP($P$35,INPUT!$A$48:$I$156,3,FALSE),"") | U35: ="<aside>🅰1️⃣"&$H$34&"<br><br><strong>🅰2️⃣"&$H$35&"</strong><br><br>🅱1️⃣___________<br><br>🅱2️⃣___________</mark>" | Y35: =INPUT!$B$7 | Z35: =INPUT!$B$8 | AA35: =IFERROR(VLOOKUP($P$35,INPUT!$A$48:$I$156,5,FALSE),"") | AB35: =IFERROR(VLOOKUP($AA$35,INPUT!$A$18:$D$24,2,FALSE),"") | AC35: =INPUT!$B$9 | AF35: =IFERROR(VLOOKUP($AA$35,INPUT!$A$18:$D$24,3,FALSE),"") | AG35: =INPUT!$B$10 | AH35: =IFERROR(VLOOKUP($AA$35,INPUT!$A$18:$D$24,4,FALSE),"") | AI35: =INPUT!$B$11 | AJ35: =INPUT!$B$12 | AK35: =INPUT!$B$13 | AL35: =INPUT!$B$14 | AM35: =INPUT!$B$15 | BD35: =IFERROR(VLOOKUP($P$35,INPUT!$A$48:$I$156,7,FALSE),"") | BE35: =IFERROR(VLOOKUP($P$35,INPUT!$A$48:$I$156,8,FALSE),"") | BF35: =IFERROR(VLOOKUP($P$35,INPUT!$A$48:$I$156,9,FALSE),"") | BG35: =IF(TRIM($Q$35)<>"",TRIM($Q$35),TRIM($R$35))
A36: =INPUT!$B$5 | B36: 03 | G36: =INPUT!$B$6 | H36: =IFERROR(VLOOKUP($P$36,INPUT!$A$48:$I$156,6,FALSE),"") | P36: wouldyourather_b03_ii03 | Q36: =IFERROR(VLOOKUP($P$36,INPUT!$A$48:$I$156,4,FALSE),"") | R36: =IFERROR(VLOOKUP($P$36,INPUT!$A$48:$I$156,3,FALSE),"") | U36: ="<aside>🅰1️⃣"&$H$34&"<br><br>🅰2️⃣"&$H$35&"<br><br><strong>🅱1️⃣"&$H$36&"</strong><br><br>🅱2️⃣___________</mark>" | Y36: =INPUT!$B$7 | Z36: =INPUT!$B$8 | AA36: =IFERROR(VLOOKUP($P$36,INPUT!$A$48:$I$156,5,FALSE),"") | AB36: =IFERROR(VLOOKUP($AA$36,INPUT!$A$18:$D$24,2,FALSE),"") | AC36: =INPUT!$B$9 | AF36: =IFERROR(VLOOKUP($AA$36,INPUT!$A$18:$D$24,3,FALSE),"") | AG36: =INPUT!$B$10 | AH36: =IFERROR(VLOOKUP($AA$36,INPUT!$A$18:$D$24,4,FALSE),"") | AI36: =INPUT!$B$11 | AJ36: =INPUT!$B$12 | AK36: =INPUT!$B$13 | AL36: =INPUT!$B$14 | AM36: =INPUT!$B$15 | BD36: =IFERROR(VLOOKUP($P$36,INPUT!$A$48:$I$156,7,FALSE),"") | BE36: =IFERROR(VLOOKUP($P$36,INPUT!$A$48:$I$156,8,FALSE),"") | BF36: =IFERROR(VLOOKUP($P$36,INPUT!$A$48:$I$156,9,FALSE),"") | BG36: =IF(TRIM($Q$36)<>"",TRIM($Q$36),TRIM($R$36))
A37: =INPUT!$B$5 | B37: 04 | G37: =INPUT!$B$6 | H37: =IFERROR(VLOOKUP($P$37,INPUT!$A$48:$I$156,6,FALSE),"") | P37: wouldyourather_b03_ii04 | Q37: =IFERROR(VLOOKUP($P$37,INPUT!$A$48:$I$156,4,FALSE),"") | R37: =IFERROR(VLOOKUP($P$37,INPUT!$A$48:$I$156,3,FALSE),"") | U37: ="<aside>🅰1️⃣"&$H$34&"<br><br>🅰2️⃣"&$H$35&"<br><br>🅱1️⃣"&$H$36&"<br><br><strong>🅱2️⃣"&$H$37&"</mark>" | Y37: =INPUT!$B$7 | Z37: =INPUT!$B$8 | AA37: =IFERROR(VLOOKUP($P$37,INPUT!$A$48:$I$156,5,FALSE),"") | AB37: =IFERROR(VLOOKUP($AA$37,INPUT!$A$18:$D$24,2,FALSE),"") | AC37: =INPUT!$B$9 | AF37: =IFERROR(VLOOKUP($AA$37,INPUT!$A$18:$D$24,3,FALSE),"") | AG37: =INPUT!$B$10 | AH37: =IFERROR(VLOOKUP($AA$37,INPUT!$A$18:$D$24,4,FALSE),"") | AI37: =INPUT!$B$11 | AJ37: =INPUT!$B$12 | AK37: =INPUT!$B$13 | AL37: =INPUT!$B$14 | AM37: =INPUT!$B$15 | BD37: =IFERROR(VLOOKUP($P$37,INPUT!$A$48:$I$156,7,FALSE),"") | BE37: =IFERROR(VLOOKUP($P$37,INPUT!$A$48:$I$156,8,FALSE),"") | BF37: =IFERROR(VLOOKUP($P$37,INPUT!$A$48:$I$156,9,FALSE),"") | BG37: =IF(TRIM($Q$37)<>"",TRIM($Q$37),TRIM($R$37))
A38: =INPUT!$B$5 | B38: 01 | G38: =INPUT!$B$6 | H38: =IFERROR(VLOOKUP($P$38,INPUT!$A$48:$I$156,6,FALSE),"") | P38: wouldyourather_c0101 | Q38: =IFERROR(VLOOKUP($P$38,INPUT!$A$48:$I$156,4,FALSE),"") | R38: =IFERROR(VLOOKUP($P$38,INPUT!$A$48:$I$156,3,FALSE),"") | U38: ="<aside><strong>🅰1️⃣"&$H$38&"</strong><br><br>🅰2️⃣___________<br><br>🅱1️⃣___________<br><br>🅱2️⃣___________></mark>" | Y38: =INPUT!$B$7 | Z38: =INPUT!$B$8 | AA38: =IFERROR(VLOOKUP($P$38,INPUT!$A$48:$I$156,5,FALSE),"") | AB38: =IFERROR(VLOOKUP($AA$38,INPUT!$A$18:$D$24,2,FALSE),"") | AC38: =INPUT!$B$9 | AF38: =IFERROR(VLOOKUP($AA$38,INPUT!$A$18:$D$24,3,FALSE),"") | AG38: =INPUT!$B$10 | AH38: =IFERROR(VLOOKUP($AA$38,INPUT!$A$18:$D$24,4,FALSE),"") | AI38: =INPUT!$B$11 | AJ38: =INPUT!$B$12 | AK38: =INPUT!$B$13 | AL38: =INPUT!$B$14 | AM38: =INPUT!$B$15 | BD38: =IFERROR(VLOOKUP($P$38,INPUT!$A$48:$I$156,7,FALSE),"") | BE38: =IFERROR(VLOOKUP($P$38,INPUT!$A$48:$I$156,8,FALSE),"") | BF38: =IFERROR(VLOOKUP($P$38,INPUT!$A$48:$I$156,9,FALSE),"") | BG38: =IF(TRIM($Q$38)<>"",TRIM($Q$38),TRIM($R$38))
A39: =INPUT!$B$5 | B39: 02 | G39: =INPUT!$B$6 | H39: =IFERROR(VLOOKUP($P$39,INPUT!$A$48:$I$156,6,FALSE),"") | P39: wouldyourather_c0102 | Q39: =IFERROR(VLOOKUP($P$39,INPUT!$A$48:$I$156,4,FALSE),"") | R39: =IFERROR(VLOOKUP($P$39,INPUT!$A$48:$I$156,3,FALSE),"") | U39: ="<aside>🅰1️⃣"&$H$38&"<br><br><strong>🅰2️⃣"&$H$39&"</strong><br><br>🅱1️⃣___________<br><br>🅱2️⃣___________</mark>" | Y39: =INPUT!$B$7 | Z39: =INPUT!$B$8 | AA39: =IFERROR(VLOOKUP($P$39,INPUT!$A$48:$I$156,5,FALSE),"") | AB39: =IFERROR(VLOOKUP($AA$39,INPUT!$A$18:$D$24,2,FALSE),"") | AC39: =INPUT!$B$9 | AF39: =IFERROR(VLOOKUP($AA$39,INPUT!$A$18:$D$24,3,FALSE),"") | AG39: =INPUT!$B$10 | AH39: =IFERROR(VLOOKUP($AA$39,INPUT!$A$18:$D$24,4,FALSE),"") | AI39: =INPUT!$B$11 | AJ39: =INPUT!$B$12 | AK39: =INPUT!$B$13 | AL39: =INPUT!$B$14 | AM39: =INPUT!$B$15 | BD39: =IFERROR(VLOOKUP($P$39,INPUT!$A$48:$I$156,7,FALSE),"") | BE39: =IFERROR(VLOOKUP($P$39,INPUT!$A$48:$I$156,8,FALSE),"") | BF39: =IFERROR(VLOOKUP($P$39,INPUT!$A$48:$I$156,9,FALSE),"") | BG39: =IF(TRIM($Q$39)<>"",TRIM($Q$39),TRIM($R$39))
A40: =INPUT!$B$5 | B40: 03 | G40: =INPUT!$B$6 | H40: =IFERROR(VLOOKUP($P$40,INPUT!$A$48:$I$156,6,FALSE),"") | P40: wouldyourather_c0103 | Q40: =IFERROR(VLOOKUP($P$40,INPUT!$A$48:$I$156,4,FALSE),"") | R40: =IFERROR(VLOOKUP($P$40,INPUT!$A$48:$I$156,3,FALSE),"") | U40: ="<aside>🅰1️⃣"&$H$38&"<br><br>🅰2️⃣"&$H$39&"<br><br><strong>🅱1️⃣"&$H$40&"</strong><br><br>🅱2️⃣___________</mark>" | Y40: =INPUT!$B$7 | Z40: =INPUT!$B$8 | AA40: =IFERROR(VLOOKUP($P$40,INPUT!$A$48:$I$156,5,FALSE),"") | AB40: =IFERROR(VLOOKUP($AA$40,INPUT!$A$18:$D$24,2,FALSE),"") | AC40: =INPUT!$B$9 | AF40: =IFERROR(VLOOKUP($AA$40,INPUT!$A$18:$D$24,3,FALSE),"") | AG40: =INPUT!$B$10 | AH40: =IFERROR(VLOOKUP($AA$40,INPUT!$A$18:$D$24,4,FALSE),"") | AI40: =INPUT!$B$11 | AJ40: =INPUT!$B$12 | AK40: =INPUT!$B$13 | AL40: =INPUT!$B$14 | AM40: =INPUT!$B$15 | BD40: =IFERROR(VLOOKUP($P$40,INPUT!$A$48:$I$156,7,FALSE),"") | BE40: =IFERROR(VLOOKUP($P$40,INPUT!$A$48:$I$156,8,FALSE),"") | BF40: =IFERROR(VLOOKUP($P$40,INPUT!$A$48:$I$156,9,FALSE),"") | BG40: =IF(TRIM($Q$40)<>"",TRIM($Q$40),TRIM($R$40))
...

Sheet INPUT
A1: INPUT — the ONLY sheet to edit. Every unique text value lives here once; MAIN is formulas. To add takes, append rows to the takes table, then append matching MAIN rows reusing the neighboring formulas. Never edit the exported CSV: it carries values only, which is how the formulas were lost.
A3: globals — one value used file-wide (MAIN references the cell)
A4: key | B4: value
A5: title_text | B5: Preferences in English<br>A1➡B2
A6: character | B6: CasualTeacher
A7: course_id | B7: wouldyourather
A8: course_name | B8: Preferences in English A1➡B2
A9: response_type | B9: friendClosedResponse
A10: recap_overlay | B10: shareCta
A11: success_video | B11: success
A12: success_srt | B12: 1 00:00:00,000 --> 00:00:06,180 Great, you're almost done. Now your shareable video is going to be magically 2 00:00:06,180 --> 00:00:11,300 created right in front of your eyes. Just wait for the video to finish then 3 00:00:11,300 --> 00:00:14,880 share it with your friends, family and colleagues so they can reply to you. 4 00:00:14,880 --> 00:00:20,580 They'll also be able to prompt you to speak. Remember to share with a lot of 5 00:00:20,580 --> 00:00:25,480 people to get more chances to practice the next 48 hours before the video is deleted. 6 00:00:25,480 --> 00:00:31,320 So press the button below to create the video, wait for it to finish, then share.
A13: success_srt_es | B13: 1 00:00:00,000 --> 00:00:06,180 Genial, ya casi terminas. Ahora tu video para compartir se creará mágicamente 2 00:00:06,180 --> 00:00:11,300 justo delante de tus ojos. Solo espera a que el video termine y luego 3 00:00:11,300 --> 00:00:14,880 compártelo con tus amigos, familiares y colegas para que puedan responderte. 4 00:00:14,880 --> 00:00:20,580 También podrán animarte a hablar. Recuerda compartir con muchas 5 00:00:20,580 --> 00:00:25,480 personas para tener más oportunidades de practicar durante las próximas 48 horas antes de que el video se elimine. 6 00:00:25,480 --> 00:00:31,320 Así que oprime el botón de abajo para crear el video, espera a que termine y luego compártelo.
A14: success_srt_pt | B14: 1 00:00:00,000 --> 00:00:06,180 Ótimo, você está quase terminando. Agora seu vídeo para compartilhar será criado magicamente 2 00:00:06,180 --> 00:00:11,300 bem diante dos seus olhos. Apenas espere o vídeo terminar e então 3 00:00:11,300 --> 00:00:14,880 compartilhe-o com seus amigos, familiares e colegas para que eles possam responder a você. 4 00:00:14,880 --> 00:00:20,580 Eles também poderão incentivar você a falar. Lembre-se de compartilhar com muitas 5 00:00:20,580 --> 00:00:25,480 pessoas para ter mais chances de praticar nas próximas 48 horas antes que o vídeo seja excluído. 6 00:00:25,480 --> 00:00:31,320 Então pressione o botão abaixo para criar o vídeo, espere ele terminar e depois compartilhe.
A15: success_srt_bn | B15: 1 00:00:00,000 --> 00:00:06,180 দুর্দান্ত, আপনি প্রায় শেষ। এখন আপনার শেয়ারযোগ্য ভিডিওটি জাদুর মতো তৈরি হবে 2 00:00:06,180 --> 00:00:11,300 আপনার চোখের সামনেই। শুধু ভিডিওটি শেষ হওয়ার জন্য অপেক্ষা করুন তারপর 3 00:00:11,300 --> 00:00:14,880 এটি আপনার বন্ধু, পরিবার এবং সহকর্মীদের সাথে শেয়ার করুন যাতে তারা আপনাকে উত্তর দিতে পারে। 4 00:00:14,880 --> 00:00:20,580 তারা আপনাকে কথা বলতে উৎসাহিতও করতে পারবে। অনেকের সাথে শেয়ার করতে মনে রাখবেন 5 00:00:20,580 --> 00:00:25,480 যাতে ভিডিওটি মুছে ফেলার আগে পরবর্তী ৪৮ ঘণ্টায় অনুশীলনের আরও সুযোগ পায়। 6 00:00:25,480 --> 00:00:31,320 তাই ভিডিও তৈরি করতে নিচের বোতামটি চাপুন, এটি শেষ হওয়ার জন্য অপেক্ষা করুন, তারপর শেয়ার করুন।
A17: lessons — one row per lesson_id (MAIN VLOOKUPs by lesson_id)
A18: lesson_id | B18: lesson_title | C18: recap_sources | D18: intro_video
A19: a | B19: Ask: money vs. time, food vs. talk, beach vs. mountains | C19: none | D19: intro
A20: b | B20: Answer: money vs. time, food vs. talk, beach vs. mountains | C20: friend | D20: {friendCode}wouldyourather-a-response-01
A21: c | B21: Ask: rich vs. free, cook vs. restaurant, alone vs. friends | C21: none | D21: {friendCode}wouldyourather-b-response-04
A22: d | B22: Answer: rich vs. free, cook vs. restaurant, alone vs. friends | C22: friend | D22: {friendCode}wouldyourather-c-response-04
A23: e | B23: Ask: time vs. money, sweet vs. salty, home vs. out | C23: none | D23: {friendCode}wouldyourather-d-response-04
A24: f | B24: Answer: time vs. money, sweet vs. salty, home vs. out | C24: friend | D24: {friendCode}wouldyourather-e-response-04
A26: steps — one row per step (join else video_file; MAIN VLOOKUPs by _step)
A27: step_key
A28: wouldyourather_a01
A29: wouldyourather_a02
A30: wouldyourather_a03
A31: wouldyourather_b01
A32: wouldyourather_b02
A33: wouldyourather_b03
A34: wouldyourather_c01
A35: wouldyourather_c02
A36: wouldyourather_c03
A37: wouldyourather_d01
... A47: takes — one row per filename; the phrase source of truth (MAIN VLOOKUPs phrase* by filename; subtitle formulas point at MAIN phrase cells)
A48: filename | B48: order | C48: video_file | D48: join | E48: lesson_id | F48: phrase | G48: phrase_es | H48: phrase_pt | I48: phrase_bn
A49: wouldyourather_a0101 | B49: 01 | C49: wouldyourather_a01 | E49: a | F49: A million dollars today or five million dollars in five years?
A50: wouldyourather_a0102 | B50: 02 | C50: wouldyourather_a01 | E50: a | F50: Is it better to a million dollars today or five million dollars in five years?
A51: wouldyourather_a0103 | B51: 03 | C51: wouldyourather_a01 | E51: a | F51: Would you rather receive a million dollars today or wait five years and receive five million dollars instead?
A52: wouldyourather_a0104 | B52: 04 | C52: wouldyourather_a01 | E52: a | F52: Given the choice between accepting a million dollars today and waiting five years for five million dollars, Is it better to do?
...
